Workbook

Sheet Assumptions
A1: LUMINA — ALL ASSUMPTIONS (Researched April 2026)
A3: FX RATES
A4: EUR/CHF | B4: 0.9224 | C4: 1 EUR = 0.9224 CHF. Multiply. ECB Apr 3 2026
A5: USD/CHF | B5: 0.8 | C5: 1 USD = 0.80 CHF. Multiply. Apr 4 2026
A6: €1,000 → CHF | B6: 922
A7: $600 → CHF | B7: 480
A9: CAPITAL
A10: Initial capital (CHF) | B10: 200000 | C10: Swiss AG share capital, hard CHF
A12: ARPU (EUR/hotel/month)
B13: Phase 1 M1-23 | C13: Phase 2 M24-36 | D13: Phase 3 M37-48
A14: Chain | B14: 1000 | C14: 1400 | D14: 1800
A15: Indie | B15: 1000 | C15: 1500 | D15: 2000
A17: CHAIN SCHEDULE (10 chains, 48 months)
A18: Kempinski: M1, 82 hotels total
A19: Radisson: M12, 95 hotels total
A20: Barceló: M16, 70 hotels total
A21: Mandarin Oriental: M20, 36 hotels total
A22: Hyatt Luxury: M24, 45 hotels total
A23: Jumeirah: M28, 26 hotels total
A24: Meliá: M32, 80 hotels total
A25: Rosewood: M36, 30 hotels total
A26: Minor Hotels: M40, 55 hotels total
A27: Rotana: M44, 42 hotels total
A28: Trial: 3 hotels free for 3 months. Rollout pays immediately.
... A33: CEO SALARY (CHF, researched social contributions)
A34: CHF 106,080 → company cost CHF 9,737/mo | B34: 9737 | C34: 10.14% employer social
A35: CHF 150,000 → company cost CHF 13,689/mo | B35: 13689 | C35: 9.51%
A36: CHF 185,000 → company cost CHF 16,817/mo | B36: 16817 | C36: 9.09%
A37: CHF 220,000 → company cost CHF 19,945/mo | B37: 19945 | C37: 8.79%
A38: Step-ups: €300K→150K, €1.5M→185K, €3M→220K + runway clause
A40: TEAM (EUR/mo total company cost per person)
A41: Developer FT: €4,000 = CHF 3,690/mo from M1
A42: PM PT: €4,000 = CHF 3,690/mo from M1
A43: CS: €5,000 = CHF 4,612/mo from M12
A44: Senior Eng: €7,000 = CHF 6,457/mo from M18
A45: Sales/BD: €6,000 = CHF 5,534/mo from M18
A46: Engineer: €6,000 = CHF 5,534/mo from M30
A47: Marketing: €5,000 = CHF 4,612/mo from M36
A49: DEV TOOLING ($600 USD = CHF 480)
A50: Claude Code Max 20x | B50: 160 | C50: $200
...

Sheet Monthly P&L
A1: LUMINA — MONTHLY P&L (CHF) — ZUG/BAAR
B3: Y1 | C3: Y1 | D3: Y1 | E3: Y1 | F3: Y1 | G3: Y1 | H3: Y1 | I3: Y1 | J3: Y1 | K3: Y1 | L3: Y1 | M3: Y1 | N3: Y2 | O3: Y2 | P3: Y2 | Q3: Y2 | R3: Y2 | S3: Y2 | T3: Y2 | U3: Y2 | V3: Y2 | W3: Y2 | X3: Y2 | Y3: Y2 | Z3: Y3 | AA3: Y3 | AB3: Y3 | AC3: Y3 | AD3: Y3 | AE3: Y3 | AF3: Y3 | AG3: Y3 | AH3: Y3 | AI3: Y3 | AJ3: Y3 | AK3: Y3 | AL3: Y4 | AM3: Y4 | AN3: Y4 | AO3: Y4 | AP3: Y4 | AQ3: Y4 | AR3: Y4 | AS3: Y4 | AT3: Y4 | AU3: Y4 | AV3: Y4 | AW3: Y4 | AX3: Y1 | AY3: Y2 | AZ3: Y3 | BA3: Y4
A4: Month | B4: M1 | C4: M2 | D4: M3 | E4: M4 | F4: M5 | G4: M6 | H4: M7 | I4: M8 | J4: M9 | K4: M10 | L4: M11 | M4: M12 | N4: M13 | O4: M14 | P4: M15 | Q4: M16 | R4: M17 | S4: M18 | T4: M19 | U4: M20 | V4: M21 | W4: M22 | X4: M23 | Y4: M24 | Z4: M25 | AA4: M26 | AB4: M27 | AC4: M28 | AD4: M29 | AE4: M30 | AF4: M31 | AG4: M32 | AH4: M33 | AI4: M34 | AJ4: M35 | AK4: M36 | AL4: M37 | AM4: M38 | AN4: M39 | AO4: M40 | AP4: M41 | AQ4: M42 | AR4: M43 | AS4: M44 | AT4: M45 | AU4: M46 | AV4: M47 | AW4: M48
A5: HOTEL COUNTS
A6: Kempinski | B6: 3 | C6: 3 | D6: 3 | E6: 3 | F6: 3 | G6: 12 | H6: 12 | I6: 12 | J6: 12 | K6: 12 | L6: 12 | M6: 33 | N6: 33 | O6: 33 | P6: 33 | Q6: 33 | R6: 33 | S6: 41 | T6: 41 | U6: 41 | V6: 41 | W6: 41 | X6: 41 | Y6: 45 | Z6: 45 | AA6: 45 | AB6: 45 | AC6: 45 | AD6: 45 | AE6: 45 | AF6: 45 | AG6: 45 | AH6: 45 | AI6: 45 | AJ6: 45 | AK6: 45 | AL6: 45 | AM6: 45 | AN6: 45 | AO6: 45 | AP6: 45 | AQ6: 45 | AR6: 45 | AS6: 45 | AT6: 45 | AU6: 45 | AV6: 45 | AW6: 45 | AX6: 33 | AY6: 45 | AZ6: 45 | BA6: 45
A7: Radisson | B7: 0 | C7: 0 | D7: 0 | E7: 0 | F7: 0 | G7: 0 | H7: 0 | I7: 0 | J7: 0 | K7: 0 | L7: 0 | M7: 3 | N7: 3 | O7: 3 | P7: 3 | Q7: 3 | R7: 14 | S7: 14 | T7: 14 | U7: 14 | V7: 14 | W7: 14 | X7: 38 | Y7: 38 | Z7: 38 | AA7: 38 | AB7: 38 | AC7: 38 | AD7: 48 | AE7: 48 | AF7: 48 | AG7: 48 | AH7: 48 | AI7: 48 | AJ7: 52 | AK7: 52 | AL7: 52 | AM7: 52 | AN7: 52 | AO7: 52 | AP7: 52 | AQ7: 52 | AR7: 52 | AS7: 52 | AT7: 52 | AU7: 52 | AV7: 52 | AW7: 52 | AX7: 3 | AY7: 38 | AZ7: 52 | BA7: 52
A8: Barceló | B8: 0 | C8: 0 | D8: 0 | E8: 0 | F8: 0 | G8: 0 | H8: 0 | I8: 0 | J8: 0 | K8: 0 | L8: 0 | M8: 0 | N8: 0 | O8: 0 | P8: 0 | Q8: 3 | R8: 3 | S8: 3 | T8: 3 | U8: 3 | V8: 10 | W8: 10 | X8: 10 | Y8: 10 | Z8: 10 | AA8: 10 | AB8: 28 | AC8: 28 | AD8: 28 | AE8: 28 | AF8: 28 | AG8: 28 | AH8: 35 | AI8: 35 | AJ8: 35 | AK8: 35 | AL8: 35 | AM8: 35 | AN8: 38 | AO8: 38 | AP8: 38 | AQ8: 38 | AR8: 38 | AS8: 38 | AT8: 38 | AU8: 38 | AV8: 38 | AW8: 38 | AX8: 0 | AY8: 10 | AZ8: 35 | BA8: 38
A9: Mandarin Oriental | B9: 0 | C9: 0 | D9: 0 | E9: 0 | F9: 0 | G9: 0 | H9: 0 | I9: 0 | J9: 0 | K9: 0 | L9: 0 | M9: 0 | N9: 0 | O9: 0 | P9: 0 | Q9: 0 | R9: 0 | S9: 0 | T9: 0 | U9: 3 | V9: 3 | W9: 3 | X9: 3 | Y9: 3 | Z9: 5 | AA9: 5 | AB9: 5 | AC9: 5 | AD9: 5 | AE9: 5 | AF9: 14 | AG9: 14 | AH9: 14 | AI9: 14 | AJ9: 14 | AK9: 14 | AL9: 18 | AM9: 18 | AN9: 18 | AO9: 18 | AP9: 18 | AQ9: 18 | AR9: 20 | AS9: 20 | AT9: 20 | AU9: 20 | AV9: 20 | AW9: 20 | AX9: 0 | AY9: 3 | AZ9: 14 | BA9: 20
A10: Hyatt Luxury | B10: 0 | C10: 0 | D10: 0 | E10: 0 | F10: 0 | G10: 0 | H10: 0 | I10: 0 | J10: 0 | K10: 0 | L10: 0 | M10: 0 | N10: 0 | O10: 0 | P10: 0 | Q10: 0 | R10: 0 | S10: 0 | T10: 0 | U10: 0 | V10: 0 | W10: 0 | X10: 0 | Y10: 3 | Z10: 3 | AA10: 3 | AB10: 3 | AC10: 3 | AD10: 7 | AE10: 7 | AF10: 7 | AG10: 7 | AH10: 7 | AI10: 7 | AJ10: 18 | AK10: 18 | AL10: 18 | AM10: 18 | AN10: 18 | AO10: 18 | AP10: 22 | AQ10: 22 | AR10: 22 | AS10: 22 | AT10: 22 | AU10: 22 | AV10: 25 | AW10: 25 | AX10: 0 | AY10: 3 | AZ10: 18 | BA10: 25
A11: Jumeirah | B11: 0 | C11: 0 | D11: 0 | E11: 0 | F11: 0 | G11: 0 | H11: 0 | I11: 0 | J11: 0 | K11: 0 | L11: 0 | M11: 0 | N11: 0 | O11: 0 | P11: 0 | Q11: 0 | R11: 0 | S11: 0 | T11: 0 | U11: 0 | V11: 0 | W11: 0 | X11: 0 | Y11: 0 | Z11: 0 | AA11: 0 | AB11: 0 | AC11: 3 | AD11: 3 | AE11: 3 | AF11: 3 | AG11: 3 | AH11: 4 | AI11: 4 | AJ11: 4 | AK11: 4 | AL11: 4 | AM11: 4 | AN11: 10 | AO11: 10 | AP11: 10 | AQ11: 10 | AR11: 10 | AS11: 10 | AT11: 13 | AU11: 13 | AV11: 13 | AW11: 13 | AX11: 0 | AY11: 0 | AZ11: 4 | BA11: 13
A12: Meliá | B12: 0 | C12: 0 | D12: 0 | E12: 0 | F12: 0 | G12: 0 | H12: 0 | I12: 0 | J12: 0 | K12: 0 | L12: 0 | M12: 0 | N12: 0 | O12: 0 | P12: 0 | Q12: 0 | R12: 0 | S12: 0 | T12: 0 | U12: 0 | V12: 0 | W12: 0 | X12: 0 | Y12: 0 | Z12: 0 | AA12: 0 | AB12: 0 | AC12: 0 | AD12: 0 | AE12: 0 | AF12: 0 | AG12: 3 | AH12: 3 | AI12: 3 | AJ12: 3 | AK12: 3 | AL12: 12 | AM12: 12 | AN12: 12 | AO12: 12 | AP12: 12 | AQ12: 12 | AR12: 32 | AS12: 32 | AT12: 32 | AU12: 32 | AV12: 32 | AW12: 32 | AX12: 0 | AY12: 0 | AZ12: 3 | BA12: 32
A13: Rosewood | B13: 0 | C13: 0 | D13: 0 | E13: 0 | F13: 0 | G13: 0 | H13: 0 | I13: 0 | J13: 0 | K13: 0 | L13: 0 | M13: 0 | N13: 0 | O13: 0 | P13: 0 | Q13: 0 | R13: 0 | S13: 0 | T13: 0 | U13: 0 | V13: 0 | W13: 0 | X13: 0 | Y13: 0 | Z13: 0 | AA13: 0 | AB13: 0 | AC13: 0 | AD13: 0 | AE13: 0 | AF13: 0 | AG13: 0 | AH13: 0 | AI13: 0 | AJ13: 0 | AK13: 3 | AL13: 3 | AM13: 3 | AN13: 3 | AO13: 3 | AP13: 4 | AQ13: 4 | AR13: 4 | AS13: 4 | AT13: 4 | AU13: 4 | AV13: 12 | AW13: 12 | AX13: 0 | AY13: 0 | AZ13: 3 | BA13: 12
A14: Minor Hotels | B14: 0 | C14: 0 | D14: 0 | E14: 0 | F14: 0 | G14: 0 | H14: 0 | I14: 0 | J14: 0 | K14: 0 | L14: 0 | M14: 0 | N14: 0 | O14: 0 | P14: 0 | Q14: 0 | R14: 0 | S14: 0 | T14: 0 | U14: 0 | V14: 0 | W14: 0 | X14: 0 | Y14: 0 | Z14: 0 | AA14: 0 | AB14: 0 | AC14: 0 | AD14: 0 | AE14: 0 | AF14: 0 | AG14: 0 | AH14: 0 | AI14: 0 | AJ14: 0 | AK14: 0 | AL14: 0 | AM14: 0 | AN14: 0 | AO14: 3 | AP14: 3 | AQ14: 3 | AR14: 3 | AS14: 3 | AT14: 8 | AU14: 8 | AV14: 8 | AW14: 8 | AX14: 0 | AY14: 0 | AZ14: 0 | BA14: 8
A15: Rotana | B15: 0 | C15: 0 | D15: 0 | E15: 0 | F15: 0 | G15: 0 | H15: 0 | I15: 0 | J15: 0 | K15: 0 | L15: 0 | M15: 0 | N15: 0 | O15: 0 | P15: 0 | Q15: 0 | R15: 0 | S15: 0 | T15: 0 | U15: 0 | V15: 0 | W15: 0 | X15: 0 | Y15: 0 | Z15: 0 | AA15: 0 | AB15: 0 | AC15: 0 | AD15: 0 | AE15: 0 | AF15: 0 | AG15: 0 | AH15: 0 | AI15: 0 | AJ15: 0 | AK15: 0 | AL15: 0 | AM15: 0 | AN15: 0 | AO15: 0 | AP15: 0 | AQ15: 0 | AR15: 0 | AS15: 3 | AT15: 3 | AU15: 3 | AV15: 3 | AW15: 3 | AX15: 0 | AY15: 0 | AZ15: 0 | BA15: 3
A16: Total chain active | B16: 3 | C16: 3 | D16: 3 | E16: 3 | F16: 3 | G16: 12 | H16: 12 | I16: 12 | J16: 12 | K16: 12 | L16: 12 | M16: 36 | N16: 36 | O16: 36 | P16: 36 | Q16: 39 | R16: 50 | S16: 58 | T16: 58 | U16: 61 | V16: 68 | W16: 68 | X16: 92 | Y16: 99 | Z16: 101 | AA16: 101 | AB16: 119 | AC16: 122 | AD16: 136 | AE16: 136 | AF16: 145 | AG16: 148 | AH16: 156 | AI16: 156 | AJ16: 171 | AK16: 174 | AL16: 187 | AM16: 187 | AN16: 196 | AO16: 199 | AP16: 204 | AQ16: 204 | AR16: 226 | AS16: 229 | AT16: 237 | AU16: 237 | AV16: 248 | AW16: 248 | AX16: 36 | AY16: 99 | AZ16: 174 | BA16: 248
A17: Independent active | B17: 0 | C17: 0 | D17: 0 | E17: 0 | F17: 0 | G17: 0 | H17: 2 | I17: 4 | J17: 6 | K17: 8 | L17: 10 | M17: 12 | N17: 14 | O17: 16 | P17: 18 | Q17: 20 | R17: 22 | S17: 24 | T17: 26 | U17: 28 | V17: 30 | W17: 32 | X17: 34 | Y17: 36 | Z17: 38 | AA17: 40 | AB17: 42 | AC17: 44 | AD17: 46 | AE17: 48 | AF17: 51 | AG17: 53 | AH17: 55 | AI17: 57 | AJ17: 59 | AK17: 61 | AL17: 63 | AM17: 65 | AN17: 67 | AO17: 69 | AP17: 71 | AQ17: 73 | AR17: 75 | AS17: 77 | AT17: 79 | AU17: 81 | AV17: 83 | AW17: 85 | AX17: 12 | AY17: 36 | AZ17: 61 | BA17: 85
... A21: TOTAL PAYING | B21: 0 | C21: 0 | D21: 0 | E21: 3 | F21: 3 | G21: 12 | H21: 14 | I21: 16 | J21: 18 | K21: 20 | L21: 22 | M21: 45 | N21: 47 | O21: 49 | P21: 54 | Q21: 56 | R21: 69 | S21: 79 | T21: 84 | U21: 86 | V21: 95 | W21: 97 | X21: 126 | Y21: 132 | Z21: 136 | AA21: 138 | AB21: 161 | AC21: 163 | AD21: 179 | AE21: 181 | AF21: 196 | AG21: 198 | AH21: 208 | AI21: 210 | AJ21: 230 | AK21: 232 | AL21: 247 | AM21: 249 | AN21: 263 | AO21: 265 | AP21: 272 | AQ21: 274 | AR21: 301 | AS21: 303 | AT21: 313 | AU21: 315 | AV21: 331 | AW21: 333 | AX21: 45 | AY21: 132 | AZ21: 232 | BA21: 333
A23: REVENUE (CHF)
A24: Chain revenue | B24: 0 | C24: 0 | D24: 0 | E24: 2767 | F24: 2767 | G24: 11069 | H24: 11069 | I24: 11069 | J24: 11069 | K24: 11069 | L24: 11069 | M24: 30439 | N24: 30439 | O24: 30439 | P24: 33206 | Q24: 33206 | R24: 43353 | S24: 50732 | T24: 53499 | U24: 53499 | V24: 59956 | W24: 59956 | X24: 84861 | Y24: 123971 | Z24: 126553 | AA24: 126553 | AB24: 153672 | AC24: 153672 | AD24: 171751 | AE24: 171751 | AF24: 187247 | AG24: 187247 | AH24: 197578 | AI24: 197578 | AJ24: 220823 | AK24: 220823 | AL24: 305499 | AM24: 305499 | AN24: 325423 | AO24: 325423 | AP24: 333724 | AQ24: 333724 | AR24: 375232 | AS24: 375232 | AT24: 388515 | AU24: 388515 | AV24: 411759 | AW24: 411759 | AX24: 102387 | AY24: 657117 | AZ24: 2115248 | BA24: 4280304
A25: Indie revenue | B25: 0 | C25: 0 | D25: 0 | E25: 0 | F25: 0 | G25: 0 | H25: 1845 | I25: 3690 | J25: 5534 | K25: 7379 | L25: 9224 | M25: 11069 | N25: 12914 | O25: 14758 | P25: 16603 | Q25: 18448 | R25: 20293 | S25: 22138 | T25: 23982 | U25: 25827 | V25: 27672 | W25: 29517 | X25: 31362 | Y25: 49810 | Z25: 52577 | AA25: 55344 | AB25: 58111 | AC25: 60878 | AD25: 63646 | AE25: 66413 | AF25: 70564 | AG25: 73331 | AH25: 76098 | AI25: 78865 | AJ25: 81632 | AK25: 84400 | AL25: 116222 | AM25: 119912 | AN25: 123602 | AO25: 127291 | AP25: 130981 | AQ25: 134670 | AR25: 138360 | AS25: 142050 | AT25: 145739 | AU25: 149429 | AV25: 153118 | AW25: 156808 | AX25: 38741 | AY25: 293324 | AZ25: 821859 | BA25: 1638182
A26: TOTAL REVENUE | B26: 0 | C26: 0 | D26: 0 | E26: 2767 | F26: 2767 | G26: 11069 | H26: 12914 | I26: 14759 | J26: 16603 | K26: 18448 | L26: 20293 | M26: 41508 | N26: 43353 | O26: 45197 | P26: 49809 | Q26: 51654 | R26: 63646 | S26: 72870 | T26: 77481 | U26: 79326 | V26: 87628 | W26: 89473 | X26: 116223 | Y26: 173781 | Z26: 179130 | AA26: 181897 | AB26: 211783 | AC26: 214550 | AD26: 235397 | AE26: 238164 | AF26: 257811 | AG26: 260578 | AH26: 273676 | AI26: 276443 | AJ26: 302455 | AK26: 305223 | AL26: 421721 | AM26: 425411 | AN26: 449025 | AO26: 452714 | AP26: 464705 | AQ26: 468394 | AR26: 513592 | AS26: 517282 | AT26: 534254 | AU26: 537944 | AV26: 564877 | AW26: 568567 | AX26: 141128 | AY26: 950441 | AZ26: 2937107 | BA26: 5918486
A27: ARR (CHF) | B27: =B26*12 | C27: =C26*12 | D27: =D26*12 | E27: =E26*12 | F27: =F26*12 | G27: =G26*12 | H27: =H26*12 | I27: =I26*12 | ... AW27: =AW26*12 | AX27: =M27 | AY27: =Y27 | AZ27: =AK27 | BA27: =AW27
A28: ARR (EUR) | B28: =B27/0.9224 | C28: =C27/0.9224 | D28: =D27/0.9224 | E28: =E27/0.9224 | F28: =F27/0.9224 | G28: =G27/0.9224 | H28: =H27/0.9224 | I28: =I27/0.9224 | ... AW28: =AW27/0.9224 | AX28: =M28 | AY28: =Y28 | AZ28: =AK28 | BA28: =AW28
A30: COSTS (CHF) — EVERY ITEM
A31: — People
A32: CEO gross salary (CHF) | B32: 8840 | C32: 8840 | D32: 8840 | E32: 8840 | F32: 8840 | G32: 8840 | H32: 8840 | I32: 8840 | J32: 8840 | K32: 8840 | L32: 8840 | M32: 12500 | N32: 12500 | O32: 12500 | P32: 12500 | Q32: 12500 | R32: 12500 | S32: 12500 | T32: 12500 | U32: 12500 | V32: 12500 | W32: 12500 | X32: 15417 | Y32: 15417 | Z32: 15417 | AA32: 15417 | AB32: 15417 | AC32: 15417 | AD32: 18333 | AE32: 18333 | AF32: 18333 | AG32: 18333 | AH32: 18333 | AI32: 18333 | AJ32: 18333 | AK32: 18333 | AL32: 18333 | AM32: 18333 | AN32: 18333 | AO32: 18333 | AP32: 18333 | AQ32: 18333 | AR32: 18333 | AS32: 18333 | AT32: 18333 | AU32: 18333 | AV32: 18333 | AW32: 18333 | AX32: 109740 | AY32: 155834 | AZ32: 208332 | BA32: 219996
A33: CEO employer social (10.1%) | B33: 897 | C33: 897 | D33: 897 | E33: 897 | F33: 897 | G33: 897 | H33: 897 | I33: 897 | J33: 897 | K33: 897 | L33: 897 | M33: 1189 | N33: 1189 | O33: 1189 | P33: 1189 | Q33: 1189 | R33: 1189 | S33: 1189 | T33: 1189 | U33: 1189 | V33: 1189 | W33: 1189 | X33: 1400 | Y33: 1400 | Z33: 1400 | AA33: 1400 | AB33: 1400 | AC33: 1400 | AD33: 1612 | AE33: 1612 | AF33: 1612 | AG33: 1612 | AH33: 1612 | AI33: 1612 | AJ33: 1612 | AK33: 1612 | AL33: 1612 | AM33: 1612 | AN33: 1612 | AO33: 1612 | AP33: 1612 | AQ33: 1612 | AR33: 1612 | AS33: 1612 | AT33: 1612 | AU33: 1612 | AV33: 1612 | AW33: 1612 | AX33: 11056 | AY33: 14690 | AZ33: 18496 | BA33: 19344
A34: Developer FT (€4K/mo) | B34: 3690 | C34: 3690 | D34: 3690 | E34: 3690 | F34: 3690 | G34: 3690 | H34: 3690 | I34: 3690 | J34: 3690 | K34: 3690 | L34: 3690 | M34: 3690 | N34: 3690 | O34: 3690 | P34: 3690 | Q34: 3690 | R34: 3690 | S34: 3690 | T34: 3690 | U34: 3690 | V34: 3690 | W34: 3690 | X34: 3690 | Y34: 3690 | Z34: 3690 | AA34: 3690 | AB34: 3690 | AC34: 3690 | AD34: 3690 | AE34: 3690 | AF34: 3690 | AG34: 3690 | AH34: 3690 | AI34: 3690 | AJ34: 3690 | AK34: 3690 | AL34: 3690 | AM34: 3690 | AN34: 3690 | AO34: 3690 | AP34: 3690 | AQ34: 3690 | AR34: 3690 | AS34: 3690 | AT34: 3690 | AU34: 3690 | AV34: 3690 | AW34: 3690 | AX34: 44280 | AY34: 44280 | AZ34: 44280 | BA34: 44280
A35: PM PT (€4K/mo) | B35: 3690 | C35: 3690 | D35: 3690 | E35: 3690 | F35: 3690 | G35: 3690 | H35: 3690 | I35: 3690 | J35: 3690 | K35: 3690 | L35: 3690 | M35: 3690 | N35: 3690 | O35: 3690 | P35: 3690 | Q35: 3690 | R35: 3690 | S35: 3690 | T35: 3690 | U35: 3690 | V35: 3690 | W35: 3690 | X35: 3690 | Y35: 3690 | Z35: 3690 | AA35: 3690 | AB35: 3690 | AC35: 3690 | AD35: 3690 | AE35: 3690 | AF35: 3690 | AG35: 3690 | AH35: 3690 | AI35: 3690 | AJ35: 3690 | AK35: 3690 | AL35: 3690 | AM35: 3690 | AN35: 3690 | AO35: 3690 | AP35: 3690 | AQ35: 3690 | AR35: 3690 | AS35: 3690 | AT35: 3690 | AU35: 3690 | AV35: 3690 | AW35: 3690 | AX35: 44280 | AY35: 44280 | AZ35: 44280 | BA35: 44280
A36: CS/Implementation (€5K/mo, M12+) | B36: 0 | C36: 0 | D36: 0 | E36: 0 | F36: 0 | G36: 0 | H36: 0 | I36: 0 | J36: 0 | K36: 0 | L36: 0 | M36: 4612 | N36: 4612 | O36: 4612 | P36: 4612 | Q36: 4612 | R36: 4612 | S36: 4612 | T36: 4612 | U36: 4612 | V36: 4612 | W36: 4612 | X36: 4612 | Y36: 4612 | Z36: 4612 | AA36: 4612 | AB36: 4612 | AC36: 4612 | AD36: 4612 | AE36: 4612 | AF36: 4612 | AG36: 4612 | AH36: 4612 | AI36: 4612 | AJ36: 4612 | AK36: 4612 | AL36: 4612 | AM36: 4612 | AN36: 4612 | AO36: 4612 | AP36: 4612 | AQ36: 4612 | AR36: 4612 | AS36: 4612 | AT36: 4612 | AU36: 4612 | AV36: 4612 | AW36: 4612 | AX36: 4612 | AY36: 55344 | AZ36: 55344 | BA36: 55344
A37: Senior Engineer (€7K/mo, M18+) | B37: 0 | C37: 0 | D37: 0 | E37: 0 | F37: 0 | G37: 0 | H37: 0 | I37: 0 | J37: 0 | K37: 0 | L37: 0 | M37: 0 | N37: 0 | O37: 0 | P37: 0 | Q37: 0 | R37: 0 | S37: 6457 | T37: 6457 | U37: 6457 | V37: 6457 | W37: 6457 | X37: 6457 | Y37: 6457 | Z37: 6457 | AA37: 6457 | AB37: 6457 | AC37: 6457 | AD37: 6457 | AE37: 6457 | AF37: 6457 | AG37: 6457 | AH37: 6457 | AI37: 6457 | AJ37: 6457 | AK37: 6457 | AL37: 6457 | AM37: 6457 | AN37: 6457 | AO37: 6457 | AP37: 6457 | AQ37: 6457 | AR37: 6457 | AS37: 6457 | AT37: 6457 | AU37: 6457 | AV37: 6457 | AW37: 6457 | AX37: 0 | AY37: 45199 | AZ37: 77484 | BA37: 77484
A38: Sales/BD (€6K/mo, M18+) | B38: 0 | C38: 0 | D38: 0 | E38: 0 | F38: 0 | G38: 0 | H38: 0 | I38: 0 | J38: 0 | K38: 0 | L38: 0 | M38: 0 | N38: 0 | O38: 0 | P38: 0 | Q38: 0 | R38: 0 | S38: 5534 | T38: 5534 | U38: 5534 | V38: 5534 | W38: 5534 | X38: 5534 | Y38: 5534 | Z38: 5534 | AA38: 5534 | AB38: 5534 | AC38: 5534 | AD38: 5534 | AE38: 5534 | AF38: 5534 | AG38: 5534 | AH38: 5534 | AI38: 5534 | AJ38: 5534 | AK38: 5534 | AL38: 5534 | AM38: 5534 | AN38: 5534 | AO38: 5534 | AP38: 5534 | AQ38: 5534 | AR38: 5534 | AS38: 5534 | AT38: 5534 | AU38: 5534 | AV38: 5534 | AW38: 5534 | AX38: 0 | AY38: 38738 | AZ38: 66408 | BA38: 66408
A39: Engineer (€6K/mo, M30+) | B39: 0 | C39: 0 | D39: 0 | E39: 0 | F39: 0 | G39: 0 | H39: 0 | I39: 0 | J39: 0 | K39: 0 | L39: 0 | M39: 0 | N39: 0 | O39: 0 | P39: 0 | Q39: 0 | R39: 0 | S39: 0 | T39: 0 | U39: 0 | V39: 0 | W39: 0 | X39: 0 | Y39: 0 | Z39: 0 | AA39: 0 | AB39: 0 | AC39: 0 | AD39: 0 | AE39: 5534 | AF39: 5534 | AG39: 5534 | AH39: 5534 | AI39: 5534 | AJ39: 5534 | AK39: 5534 | AL39: 5534 | AM39: 5534 | AN39: 5534 | AO39: 5534 | AP39: 5534 | AQ39: 5534 | AR39: 5534 | AS39: 5534 | AT39: 5534 | AU39: 5534 | AV39: 5534 | AW39: 5534 | AX39: 0 | AY39: 0 | AZ39: 38738 | BA39: 66408
A40: Marketing (€5K/mo, M36+) | B40: 0 | C40: 0 | D40: 0 | E40: 0 | F40: 0 | G40: 0 | H40: 0 | I40: 0 | J40: 0 | K40: 0 | L40: 0 | M40: 0 | N40: 0 | O40: 0 | P40: 0 | Q40: 0 | R40: 0 | S40: 0 | T40: 0 | U40: 0 | V40: 0 | W40: 0 | X40: 0 | Y40: 0 | Z40: 0 | AA40: 0 | AB40: 0 | AC40: 0 | AD40: 0 | AE40: 0 | AF40: 0 | AG40: 0 | AH40: 0 | AI40: 0 | AJ40: 0 | AK40: 4612 | AL40: 4612 | AM40: 4612 | AN40: 4612 | AO40: 4612 | AP40: 4612 | AQ40: 4612 | AR40: 4612 | AS40: 4612 | AT40: 4612 | AU40: 4612 | AV40: 4612 | AW40: 4612 | AX40: 0 | AY40: 0 | AZ40: 4612 | BA40: 55344
A41: — AI & Technology
A42: AI COGS (€50/hotel/mo) | B42: 0 | C42: 0 | D42: 0 | E42: 138 | F42: 138 | G42: 553 | H42: 646 | I42: 738 | J42: 830 | K42: 922 | L42: 1015 | M42: 2075 | N42: 2168 | O42: 2260 | P42: 2490 | Q42: 2583 | R42: 3182 | S42: 3643 | T42: 3874 | U42: 3966 | V42: 4381 | W42: 4474 | X42: 5811 | Y42: 6088 | Z42: 6272 | AA42: 6365 | AB42: 7425 | AC42: 7518 | AD42: 8255 | AE42: 8348 | AF42: 9040 | AG42: 9132 | AH42: 9593 | AI42: 9685 | AJ42: 10608 | AK42: 10700 | AL42: 11392 | AM42: 11484 | AN42: 12130 | AO42: 12222 | AP42: 12545 | AQ42: 12637 | AR42: 13882 | AS42: 13974 | AT42: 14436 | AU42: 14528 | AV42: 15266 | AW42: 15358 | AX42: 7055 | AY42: 44920 | AZ42: 102941 | BA42: 159854
A43: Claude Code Max 20x ($200) | B43: 160 | C43: 160 | D43: 160 | E43: 160 | F43: 160 | G43: 160 | H43: 160 | I43: 160 | J43: 160 | K43: 160 | L43: 160 | M43: 160 | N43: 160 | O43: 160 | P43: 160 | Q43: 160 | R43: 160 | S43: 160 | T43: 160 | U43: 160 | V43: 160 | W43: 160 | X43: 160 | Y43: 160 | Z43: 160 | AA43: 160 | AB43: 160 | AC43: 160 | AD43: 160 | AE43: 160 | AF43: 160 | AG43: 160 | AH43: 160 | AI43: 160 | AJ43: 160 | AK43: 160 | AL43: 160 | AM43: 160 | AN43: 160 | AO43: 160 | AP43: 160 | AQ43: 160 | AR43: 160 | AS43: 160 | AT43: 160 | AU43: 160 | AV43: 160 | AW43: 160 | AX43: 1920 | AY43: 1920 | AZ43: 1920 | BA43: 1920
A44: OpenAI Codex Pro ($200) | B44: 160 | C44: 160 | D44: 160 | E44: 160 | F44: 160 | G44: 160 | H44: 160 | I44: 160 | J44: 160 | K44: 160 | L44: 160 | M44: 160 | N44: 160 | O44: 160 | P44: 160 | Q44: 160 | R44: 160 | S44: 160 | T44: 160 | U44: 160 | V44: 160 | W44: 160 | X44: 160 | Y44: 160 | Z44: 160 | AA44: 160 | AB44: 160 | AC44: 160 | AD44: 160 | AE44: 160 | AF44: 160 | AG44: 160 | AH44: 160 | AI44: 160 | AJ44: 160 | AK44: 160 | AL44: 160 | AM44: 160 | AN44: 160 | AO44: 160 | AP44: 160 | AQ44: 160 | AR44: 160 | AS44: 160 | AT44: 160 | AU44: 160 | AV44: 160 | AW44: 160 | AX44: 1920 | AY44: 1920 | AZ44: 1920 | BA44: 1920
A45: Perplexity Max ($200) | B45: 160 | C45: 160 | D45: 160 | E45: 160 | F45: 160 | G45: 160 | H45: 160 | I45: 160 | J45: 160 | K45: 160 | L45: 160 | M45: 160 | N45: 160 | O45: 160 | P45: 160 | Q45: 160 | R45: 160 | S45: 160 | T45: 160 | U45: 160 | V45: 160 | W45: 160 | X45: 160 | Y45: 160 | Z45: 160 | AA45: 160 | AB45: 160 | AC45: 160 | AD45: 160 | AE45: 160 | AF45: 160 | AG45: 160 | AH45: 160 | AI45: 160 | AJ45: 160 | AK45: 160 | AL45: 160 | AM45: 160 | AN45: 160 | AO45: 160 | AP45: 160 | AQ45: 160 | AR45: 160 | AS45: 160 | AT45: 160 | AU45: 160 | AV45: 160 | AW45: 160 | AX45: 1920 | AY45: 1920 | AZ45: 1920 | BA45: 1920
A46: — Infrastructure (SaaS)
...

Sheet Cash Flow
A1: LUMINA — CASH FLOW (CHF) — ZUG/BAAR
B3: Y1 | C3: Y1 | D3: Y1 | E3: Y1 | F3: Y1 | G3: Y1 | H3: Y1 | I3: Y1 | J3: Y1 | K3: Y1 | L3: Y1 | M3: Y1 | N3: Y2 | O3: Y2 | P3: Y2 | Q3: Y2 | R3: Y2 | S3: Y2 | T3: Y2 | U3: Y2 | V3: Y2 | W3: Y2 | X3: Y2 | Y3: Y2 | Z3: Y3 | AA3: Y3 | AB3: Y3 | AC3: Y3 | AD3: Y3 | AE3: Y3 | AF3: Y3 | AG3: Y3 | AH3: Y3 | AI3: Y3 | AJ3: Y3 | AK3: Y3 | AL3: Y4 | AM3: Y4 | AN3: Y4 | AO3: Y4 | AP3: Y4 | AQ3: Y4 | AR3: Y4 | AS3: Y4 | AT3: Y4 | AU3: Y4 | AV3: Y4 | AW3: Y4 | AX3: Y1 | AY3: Y2 | AZ3: Y3 | BA3: Y4
A4: Month | B4: M1 | C4: M2 | D4: M3 | E4: M4 | F4: M5 | G4: M6 | H4: M7 | I4: M8 | J4: M9 | K4: M10 | L4: M11 | M4: M12 | N4: M13 | O4: M14 | P4: M15 | Q4: M16 | R4: M17 | S4: M18 | T4: M19 | U4: M20 | V4: M21 | W4: M22 | X4: M23 | Y4: M24 | Z4: M25 | AA4: M26 | AB4: M27 | AC4: M28 | AD4: M29 | AE4: M30 | AF4: M31 | AG4: M32 | AH4: M33 | AI4: M34 | AJ4: M35 | AK4: M36 | AL4: M37 | AM4: M38 | AN4: M39 | AO4: M40 | AP4: M41 | AQ4: M42 | AR4: M43 | AS4: M44 | AT4: M45 | AU4: M46 | AV4: M47 | AW4: M48
A5: CASH INFLOWS
A6: Initial capital (CHF 200K) | B6: 200000 | C6: 0 | D6: 0 | E6: 0 | F6: 0 | G6: 0 | H6: 0 | I6: 0 | J6: 0 | K6: 0 | L6: 0 | M6: 0 | N6: 0 | O6: 0 | P6: 0 | Q6: 0 | R6: 0 | S6: 0 | T6: 0 | U6: 0 | V6: 0 | W6: 0 | X6: 0 | Y6: 0 | Z6: 0 | AA6: 0 | AB6: 0 | AC6: 0 | AD6: 0 | AE6: 0 | AF6: 0 | AG6: 0 | AH6: 0 | AI6: 0 | AJ6: 0 | AK6: 0 | AL6: 0 | AM6: 0 | AN6: 0 | AO6: 0 | AP6: 0 | AQ6: 0 | AR6: 0 | AS6: 0 | AT6: 0 | AU6: 0 | AV6: 0 | AW6: 0 | AX6: 200000 | AY6: 0 | AZ6: 0 | BA6: 0
A7: Revenue | B7: ='Monthly P&L'!B26 | C7: ='Monthly P&L'!C26 | D7: ='Monthly P&L'!D26 | E7: ='Monthly P&L'!E26 | F7: ='Monthly P&L'!F26 | G7: ='Monthly P&L'!G26 | H7: ='Monthly P&L'!H26 | I7: ='Monthly P&L'!I26 | ... BA7: ='Monthly P&L'!BA26
A8: TOTAL INFLOWS | B8: =B6+B7 | C8: =C6+C7 | D8: =D6+D7 | E8: =E6+E7 | F8: =F6+F7 | G8: =G6+G7 | H8: =H6+H7 | I8: =I6+I7 | ... BA8: =BA6+BA7
A10: CASH OUTFLOWS — EVERY ITEM
A11: — People
A12: CEO gross salary (CHF) | B12: ='Monthly P&L'!B32 | C12: ='Monthly P&L'!C32 | D12: ='Monthly P&L'!D32 | E12: ='Monthly P&L'!E32 | F12: ='Monthly P&L'!F32 | G12: ='Monthly P&L'!G32 | H12: ='Monthly P&L'!H32 | I12: ='Monthly P&L'!I32 | ... BA12: ='Monthly P&L'!BA32
A13: CEO employer social (10.1%) | B13: ='Monthly P&L'!B33 | C13: ='Monthly P&L'!C33 | D13: ='Monthly P&L'!D33 | E13: ='Monthly P&L'!E33 | F13: ='Monthly P&L'!F33 | G13: ='Monthly P&L'!G33 | H13: ='Monthly P&L'!H33 | I13: ='Monthly P&L'!I33 | ... BA13: ='Monthly P&L'!BA33
A14: Developer FT (€4K/mo) | B14: ='Monthly P&L'!B34 | C14: ='Monthly P&L'!C34 | D14: ='Monthly P&L'!D34 | E14: ='Monthly P&L'!E34 | F14: ='Monthly P&L'!F34 | G14: ='Monthly P&L'!G34 | H14: ='Monthly P&L'!H34 | I14: ='Monthly P&L'!I34 | ... BA14: ='Monthly P&L'!BA34
A15: PM PT (€4K/mo) | B15: ='Monthly P&L'!B35 | C15: ='Monthly P&L'!C35 | D15: ='Monthly P&L'!D35 | E15: ='Monthly P&L'!E35 | F15: ='Monthly P&L'!F35 | G15: ='Monthly P&L'!G35 | H15: ='Monthly P&L'!H35 | I15: ='Monthly P&L'!I35 | ... BA15: ='Monthly P&L'!BA35
A16: CS/Implementation (€5K/mo, M12+) | B16: ='Monthly P&L'!B36 | C16: ='Monthly P&L'!C36 | D16: ='Monthly P&L'!D36 | E16: ='Monthly P&L'!E36 | F16: ='Monthly P&L'!F36 | G16: ='Monthly P&L'!G36 | H16: ='Monthly P&L'!H36 | I16: ='Monthly P&L'!I36 | ... BA16: ='Monthly P&L'!BA36
A17: Senior Engineer (€7K/mo, M18+) | B17: ='Monthly P&L'!B37 | C17: ='Monthly P&L'!C37 | D17: ='Monthly P&L'!D37 | E17: ='Monthly P&L'!E37 | F17: ='Monthly P&L'!F37 | G17: ='Monthly P&L'!G37 | H17: ='Monthly P&L'!H37 | I17: ='Monthly P&L'!I37 | ... BA17: ='Monthly P&L'!BA37
A18: Sales/BD (€6K/mo, M18+) | B18: ='Monthly P&L'!B38 | C18: ='Monthly P&L'!C38 | D18: ='Monthly P&L'!D38 | E18: ='Monthly P&L'!E38 | F18: ='Monthly P&L'!F38 | G18: ='Monthly P&L'!G38 | H18: ='Monthly P&L'!H38 | I18: ='Monthly P&L'!I38 | ... BA18: ='Monthly P&L'!BA38
A19: Engineer (€6K/mo, M30+) | B19: ='Monthly P&L'!B39 | C19: ='Monthly P&L'!C39 | D19: ='Monthly P&L'!D39 | E19: ='Monthly P&L'!E39 | F19: ='Monthly P&L'!F39 | G19: ='Monthly P&L'!G39 | H19: ='Monthly P&L'!H39 | I19: ='Monthly P&L'!I39 | ... BA19: ='Monthly P&L'!BA39
A20: Marketing (€5K/mo, M36+) | B20: ='Monthly P&L'!B40 | C20: ='Monthly P&L'!C40 | D20: ='Monthly P&L'!D40 | E20: ='Monthly P&L'!E40 | F20: ='Monthly P&L'!F40 | G20: ='Monthly P&L'!G40 | H20: ='Monthly P&L'!H40 | I20: ='Monthly P&L'!I40 | ... BA20: ='Monthly P&L'!BA40
A21: — AI & Technology
A22: AI COGS (€50/hotel/mo) | B22: ='Monthly P&L'!B42 | C22: ='Monthly P&L'!C42 | D22: ='Monthly P&L'!D42 | E22: ='Monthly P&L'!E42 | F22: ='Monthly P&L'!F42 | G22: ='Monthly P&L'!G42 | H22: ='Monthly P&L'!H42 | I22: ='Monthly P&L'!I42 | ... BA22: ='Monthly P&L'!BA42
A23: Claude Code Max 20x ($200) | B23: ='Monthly P&L'!B43 | C23: ='Monthly P&L'!C43 | D23: ='Monthly P&L'!D43 | E23: ='Monthly P&L'!E43 | F23: ='Monthly P&L'!F43 | G23: ='Monthly P&L'!G43 | H23: ='Monthly P&L'!H43 | I23: ='Monthly P&L'!I43 | ... BA23: ='Monthly P&L'!BA43
A24: OpenAI Codex Pro ($200) | B24: ='Monthly P&L'!B44 | C24: ='Monthly P&L'!C44 | D24: ='Monthly P&L'!D44 | E24: ='Monthly P&L'!E44 | F24: ='Monthly P&L'!F44 | G24: ='Monthly P&L'!G44 | H24: ='Monthly P&L'!H44 | I24: ='Monthly P&L'!I44 | ... BA24: ='Monthly P&L'!BA44
A25: Perplexity Max ($200) | B25: ='Monthly P&L'!B45 | C25: ='Monthly P&L'!C45 | D25: ='Monthly P&L'!D45 | E25: ='Monthly P&L'!E45 | F25: ='Monthly P&L'!F45 | G25: ='Monthly P&L'!G45 | H25: ='Monthly P&L'!H45 | I25: ='Monthly P&L'!I45 | ... BA25: ='Monthly P&L'!BA45
A26: — Infrastructure (SaaS)
A27: Supabase Pro + compute | B27: ='Monthly P&L'!B47 | C27: ='Monthly P&L'!C47 | D27: ='Monthly P&L'!D47 | E27: ='Monthly P&L'!E47 | F27: ='Monthly P&L'!F47 | G27: ='Monthly P&L'!G47 | H27: ='Monthly P&L'!H47 | I27: ='Monthly P&L'!I47 | ... BA27: ='Monthly P&L'!BA47
A28: Vercel Pro | B28: ='Monthly P&L'!B48 | C28: ='Monthly P&L'!C48 | D28: ='Monthly P&L'!D48 | E28: ='Monthly P&L'!E48 | F28: ='Monthly P&L'!F48 | G28: ='Monthly P&L'!G48 | H28: ='Monthly P&L'!H48 | I28: ='Monthly P&L'!I48 | ... BA28: ='Monthly P&L'!BA48
A29: DataForSEO usage | B29: ='Monthly P&L'!B49 | C29: ='Monthly P&L'!C49 | D29: ='Monthly P&L'!D49 | E29: ='Monthly P&L'!E49 | F29: ='Monthly P&L'!F49 | G29: ='Monthly P&L'!G49 | H29: ='Monthly P&L'!H49 | I29: ='Monthly P&L'!I49 | ... BA29: ='Monthly P&L'!BA49
A30: SerpApi Developer | B30: ='Monthly P&L'!B50 | C30: ='Monthly P&L'!C50 | D30: ='Monthly P&L'!D50 | E30: ='Monthly P&L'!E50 | F30: ='Monthly P&L'!F50 | G30: ='Monthly P&L'!G50 | H30: ='Monthly P&L'!H50 | I30: ='Monthly P&L'!I50 | ... BA30: ='Monthly P&L'!BA50
A31: Firecrawl | B31: ='Monthly P&L'!B51 | C31: ='Monthly P&L'!C51 | D31: ='Monthly P&L'!D51 | E31: ='Monthly P&L'!E51 | F31: ='Monthly P&L'!F51 | G31: ='Monthly P&L'!G51 | H31: ='Monthly P&L'!H51 | I31: ='Monthly P&L'!I51 | ... BA31: ='Monthly P&L'!BA51
A32: Google Workspace | B32: ='Monthly P&L'!B52 | C32: ='Monthly P&L'!C52 | D32: ='Monthly P&L'!D52 | E32: ='Monthly P&L'!E52 | F32: ='Monthly P&L'!F52 | G32: ='Monthly P&L'!G52 | H32: ='Monthly P&L'!H52 | I32: ='Monthly P&L'!I52 | ... BA32: ='Monthly P&L'!BA52
A33: Domain .ai renewal | B33: ='Monthly P&L'!B53 | C33: ='Monthly P&L'!C53 | D33: ='Monthly P&L'!D53 | E33: ='Monthly P&L'!E53 | F33: ='Monthly P&L'!F53 | G33: ='Monthly P&L'!G53 | H33: ='Monthly P&L'!H53 | I33: ='Monthly P&L'!I53 | ... BA33: ='Monthly P&L'!BA53
A34: 1Password Business | B34: ='Monthly P&L'!B54 | C34: ='Monthly P&L'!C54 | D34: ='Monthly P&L'!D54 | E34: ='Monthly P&L'!E54 | F34: ='Monthly P&L'!F54 | G34: ='Monthly P&L'!G54 | H34: ='Monthly P&L'!H54 | I34: ='Monthly P&L'!I54 | ... BA34: ='Monthly P&L'!BA54
A35: Canva Pro | B35: ='Monthly P&L'!B55 | C35: ='Monthly P&L'!C55 | D35: ='Monthly P&L'!D55 | E35: ='Monthly P&L'!E55 | F35: ='Monthly P&L'!F55 | G35: ='Monthly P&L'!G55 | H35: ='Monthly P&L'!H55 | I35: ='Monthly P&L'!I55 | ... BA35: ='Monthly P&L'!BA55
A36: Sentry monitoring | B36: ='Monthly P&L'!B56 | C36: ='Monthly P&L'!C56 | D36: ='Monthly P&L'!D56 | E36: ='Monthly P&L'!E56 | F36: ='Monthly P&L'!F56 | G36: ='Monthly P&L'!G56 | H36: ='Monthly P&L'!H56 | I36: ='Monthly P&L'!I56 | ... BA36: ='Monthly P&L'!BA56
A37: Resend email | B37: ='Monthly P&L'!B57 | C37: ='Monthly P&L'!C57 | D37: ='Monthly P&L'!D57 | E37: ='Monthly P&L'!E57 | F37: ='Monthly P&L'!F57 | G37: ='Monthly P&L'!G57 | H37: ='Monthly P&L'!H57 | I37: ='Monthly P&L'!I57 | ... BA37: ='Monthly P&L'!BA57
A38: Notion | B38: ='Monthly P&L'!B58 | C38: ='Monthly P&L'!C58 | D38: ='Monthly P&L'!D58 | E38: ='Monthly P&L'!E58 | F38: ='Monthly P&L'!F58 | G38: ='Monthly P&L'!G58 | H38: ='Monthly P&L'!H58 | I38: ='Monthly P&L'!I58 | ... BA38: ='Monthly P&L'!BA58
A39: Cloudflare Pro | B39: ='Monthly P&L'!B59 | C39: ='Monthly P&L'!C59 | D39: ='Monthly P&L'!D59 | E39: ='Monthly P&L'!E59 | F39: ='Monthly P&L'!F59 | G39: ='Monthly P&L'!G59 | H39: ='Monthly P&L'!H59 | I39: ='Monthly P&L'!I59 | ... BA39: ='Monthly P&L'!BA59
A40: — Admin & Professional
A41: Slack Pro | B41: ='Monthly P&L'!B61 | C41: ='Monthly P&L'!C61 | D41: ='Monthly P&L'!D61 | E41: ='Monthly P&L'!E61 | F41: ='Monthly P&L'!F61 | G41: ='Monthly P&L'!G61 | H41: ='Monthly P&L'!H61 | I41: ='Monthly P&L'!I61 | ... BA41: ='Monthly P&L'!BA61
A42: GitHub Actions (CI/CD) | B42: ='Monthly P&L'!B62 | C42: ='Monthly P&L'!C62 | D42: ='Monthly P&L'!D62 | E42: ='Monthly P&L'!E62 | F42: ='Monthly P&L'!F62 | G42: ='Monthly P&L'!G62 | H42: ='Monthly P&L'!H62 | I42: ='Monthly P&L'!I62 | ... BA42: ='Monthly P&L'!BA62
...

Sheet Zug vs Zurich
A1: ZUG/BAAR vs ZURICH — FULL COMPARISON
A3: CORPORATE PROFIT TAX
B4: Baar/Zug | C4: Zurich City | D4: Annual Savings
A5: Effective rate | B5: 11.82% | C5: 19.59% | D5: -7.77pp
A6: Tax on CHF 100,000 profit | B6: 11820 | C6: 19590 | D6: 7770
A7: Tax on CHF 500,000 profit | B7: 59100 | C7: 97950 | D7: 38850
A8: Tax on CHF 1,000,000 profit | B8: 118200 | C8: 195900 | D8: 77700
A10: AFTER-TAX PROFIT BY YEAR
A11: Year | B11: EBITDA | C11: Tax (Zug) | D11: After-tax (Zug) | E11: Tax (Zurich) | F11: After-tax (ZH) | G11: Zug saves
A12: Y1 | B12: -133825 | C12: 0 | D12: -133825 | E12: 0 | F12: -133825 | G12: 0
A13: Y2 | B13: 415163 | C13: 49072 | D13: 366091 | E13: 81330 | F13: 333833 | G13: 32258
A14: Y3 | B14: 2097396 | C14: 247912 | D14: 1849484 | E14: 410880 | F14: 1686516 | G14: 162968
A15: Y4 | B15: 4814350 | C15: 569056 | D15: 4245294 | E15: 943131 | F15: 3871219 | G15: 374075
A16: CUMULATIVE TAX SAVINGS (ZUG) | G16: 569301
A18: OTHER DIFFERENCES
A19: Incorporation notary fee | B19: CHF 1,000 | C19: CHF 1,500 | D19: CHF 500 more
A20: FAK employer rate | B20: 1.35% | C20: 0.98% | D20: ~CHF 400/yr cheaper in ZH per employee
A21: Capital tax rate | B21: 0.07% | C21: 0.17% | D21: CHF 200 more/yr at CHF 200K equity
A22: Treuhand costs | B22: Similar | C22: Similar | D22: 10-20% higher in ZH on average
A23: Domiciliation | B23: CHF 29/mo basic | C23: CHF 50/mo basic | D23: Minimal difference
A24: Insurance | B24: Same | C24: Same | D24: Not canton-dependent
A26: VERDICT: Zug/Baar saves CHF 38K-78K/year in corporate tax alone.
A27: Incorporation cost difference is negligible. Choose Zug.

Sheet Valuation & Exit
A1: LUMINA — VALUATION & EXIT
A3: ARR MILESTONES
B4: ARR CHF | C4: ARR EUR | D4: Paying | E4: EBITDA/mo | F4: Cash
A5: M12 | B5: 498096 | C5: 540000 | D5: 45 | E5: 9376 | F5: 66175
A6: M24 | B6: 2085372 | C6: 2260811 | D6: 132 | E6: 116390 | F6: 481338
A7: M36 | B7: 3662676 | C7: 3970811 | D7: 232 | E7: 223735 | F7: 2578734
A8: M48 | B8: 6822804 | C8: 7396795 | D8: 333 | E8: 472258 | F8: 7393084
A10: VALUATION MATRIX (CHF)
B11: 6x | C11: 8x | D11: 10x | E11: 12x
A12: M12 | B12: 2988576 | C12: 3984768 | D12: 4980960 | E12: 5977152
A13: M24 | B13: 12512232 | C13: 16682976 | D13: 20853720 | E13: 25024464
A14: M36 | B14: 21976056 | C14: 29301408 | D14: 36626760 | E14: 43952112
A15: M48 | B15: 40936824 | C15: 54582432 | D15: 68228040 | E15: 81873648
A17: MARCO'S EQUITY VALUE (10x exit)
A18: M12: 20% kicker | B18: 996192 | C18: on CHF 4,980,960 valuation
A19: M24: 20% kicker | B19: 4170744 | C19: on CHF 20,853,720 valuation
A20: M36: 23% kicker | B20: 8424155 | C20: on CHF 36,626,760 valuation
A21: M48: 25% kicker | B21: 17057010 | C21: on CHF 68,228,040 valuation

Sheet Sensitivity
A1: LUMINA — SENSITIVITY & RUNWAY
A3: BREAKEVEN
A4: First EBITDA-positive | B4: M12
A5: Lowest cash | B5: 56799 | C5: M11
A6: Max drawdown | B6: 143201
A8: CEO STEP-UP TIMELINE
A9: M1: CHF 106,080/yr → CHF 9,737/mo
A10: M12: CHF 150,000/yr → CHF 13,689/mo
A11: M23: CHF 185,000/yr → CHF 16,817/mo
A12: M29: CHF 220,000/yr → CHF 19,945/mo
A14: VESTING STATUS
A15: M12: +5% if 15+ paying | B15: MET | C15: Cumul 25%
A16: M24: +7% if ARR≥€500K | B16: MET | C16: Cumul 32%
A17: M36: +8% if ARR≥€1.5M | B17: MET | C17: Cumul 40%
